Here's the error now, looks like we are executing in the usr/ directory:

{
  "changed": true,
  "stdout": "[8989898] Starting script execution.\nGon Get API Key.\nUsername: t3-admin, password: Px3Kx[8SxN\nTrying to get. URL is 'https://100.66.31.9/api'",
  "stderr": "Traceback (most recent call last):\n  File \"/usr/local/lib/python3.9/site-packages/urllib3/connection.py\", line 174, in _new_conn\n    conn = connection.create_connection(\n  File \"/usr/local/lib/python3.9/site-packages/urllib3/util/connection.py\", line 95, in create_connection\n    raise err\n  File \"/usr/local/lib/python3.9/site-packages/urllib3/util/connection.py\", line 85, in create_connection\n    sock.connect(sa)\nOSError: [Errno 101] Network is unreachable\n\nDuring handling of the above exception, another exception occurred:\n\nTraceback (most recent call last):\n  File \"/usr/local/lib/python3.9/site-packages/urllib3/connectionpool.py\", line 715, in urlopen\n    httplib_response = self._make_request(\n  File \"/usr/local/lib/python3.9/site-packages/urllib3/connectionpool.py\", line 404, in _make_request\n    self._validate_conn(conn)\n  File \"/usr/local/lib/python3.9/site-packages/urllib3/connectionpool.py\", line 1060, in _validate_conn\n    conn.connect()\n  File \"/usr/local/lib/python3.9/site-packages/urllib3/connection.py\", line 363, in connect\n    self.sock = conn = self._new_conn()\n  File \"/usr/local/lib/python3.9/site-packages/urllib3/connection.py\", line 186, in _new_conn\n    raise NewConnectionError(\nurllib3.exceptions.NewConnectionError: <urllib3.connection.HTTPSConnection object at 0x7f6469eae5b0>: Failed to establish a new connection: [Errno 101] Network is unreachable\n\nDuring handling of the above exception, another exception occurred:\n\nTraceback (most recent call last):\n  File \"/usr/local/lib/python3.9/site-packages/requests/adapters.py\", line 667, in send\n    resp = conn.urlopen(\n  File \"/usr/local/lib/python3.9/site-packages/urllib3/connectionpool.py\", line 801, in urlopen\n    retries = retries.increment(\n  File \"/usr/local/lib/python3.9/site-packages/urllib3/util/retry.py\", line 594, in increment\n    raise MaxRetryError(_pool, url, error or ResponseError(cause))\nurllib3.exceptions.MaxRetryError: HTTPSConnectionPool(host='100.66.31.9', port=443): Max retries exceeded with url: /api?type=keygen&user=t3-admin&password=Px3Kx%5B8SxN (Caused by NewConnectionError('<urllib3.connection.HTTPSConnection object at 0x7f6469eae5b0>: Failed to establish a new connection: [Errno 101] Network is unreachable'))\n\nDuring handling of the above exception, another exception occurred:\n\nTraceback (most recent call last):\n  File \"/tmp/palo_scripts/main.py\", line 67, in get_api_key\n    response = requests.get(url, params=params, verify=False)\n  File \"/usr/local/lib/python3.9/site-packages/requests/api.py\", line 73, in get\n    return request(\"get\", url, params=params, **kwargs)\n  File \"/usr/local/lib/python3.9/site-packages/requests/api.py\", line 59, in request\n    return session.request(method=method, url=url, **kwargs)\n  File \"/usr/local/lib/python3.9/site-packages/requests/sessions.py\", line 589, in request\n    resp = self.send(prep, **send_kwargs)\n  File \"/usr/local/lib/python3.9/site-packages/requests/sessions.py\", line 703, in send\n    r = adapter.send(request, **kwargs)\n  File \"/usr/local/lib/python3.9/site-packages/requests/adapters.py\", line 700, in send\n    raise ConnectionError(e, request=request)\nrequests.exceptions.ConnectionError: HTTPSConnectionPool(host='100.66.31.9', port=443): Max retries exceeded with url: /api?type=keygen&user=t3-admin&password=Px3Kx%5B8SxN (Caused by NewConnectionError('<urllib3.connection.HTTPSConnection object at 0x7f6469eae5b0>: Failed to establish a new connection: [Errno 101] Network is unreachable'))\n\nDuring handling of the above exception, another exception occurred:\n\nTraceback (most recent call last):\n  File \"/tmp/palo_scripts/main.py\", line 176, in <module>\n    main()\n  File \"/tmp/palo_scripts/main.py\", line 104, in main\n    api_key = get_api_key(palo_ip, username, password)\n  File \"/tmp/palo_scripts/main.py\", line 82, in get_api_key\n    raise Exception(f\"An error occurred during the API Key retreival from device {palo_ip}: {e}\")\nException: An error occurred during the API Key retreival from device 100.66.31.9: HTTPSConnectionPool(host='100.66.31.9', port=443): Max retries exceeded with url: /api?type=keygen&user=t3-admin&password=Px3Kx%5B8SxN (Caused by NewConnectionError('<urllib3.connection.HTTPSConnection object at 0x7f6469eae5b0>: Failed to establish a new connection: [Errno 101] Network is unreachable'))",
  "rc": 1,
  "cmd": [
    "python3",
    "/tmp/palo_scripts/main.py"
  ],
  "start": "2025-04-29 09:58:06.240772",
  "end": "2025-04-29 09:58:09.432866",
  "delta": "0:00:03.192094",
  "msg": "non-zero return code",
  "invocation": {
    "module_args": {
      "_raw_params": "python3 /tmp/palo_scripts/main.py\n",
      "_uses_shell": false,
      "stdin_add_newline": true,
      "strip_empty_ends": true,
      "argv": null,
      "chdir": null,
      "executable": null,
      "creates": null,
      "removes": null,
      "stdin": null
    }
  },
  "stdout_lines": [
    "[8989898] Starting script execution.",
    "Gon Get API Key.",
    "Username: t3-admin, password: Px3Kx[8SxN",
    "Trying to get. URL is 'https://100.66.31.9/api'"
  ],
  "stderr_lines": [
    "Traceback (most recent call last):",
    "  File \"/usr/local/lib/python3.9/site-packages/urllib3/connection.py\", line 174, in _new_conn",
    "    conn = connection.create_connection(",
    "  File \"/usr/local/lib/python3.9/site-packages/urllib3/util/connection.py\", line 95, in create_connection",
    "    raise err",
    "  File \"/usr/local/lib/python3.9/site-packages/urllib3/util/connection.py\", line 85, in create_connection",
    "    sock.connect(sa)",
    "OSError: [Errno 101] Network is unreachable",
    "",
    "During handling of the above exception, another exception occurred:",
    "",
    "Traceback (most recent call last):",
    "  File \"/usr/local/lib/python3.9/site-packages/urllib3/connectionpool.py\", line 715, in urlopen",
    "    httplib_response = self._make_request(",
    "  File \"/usr/local/lib/python3.9/site-packages/urllib3/connectionpool.py\", line 404, in _make_request",
    "    self._validate_conn(conn)",
    "  File \"/usr/local/lib/python3.9/site-packages/urllib3/connectionpool.py\", line 1060, in _validate_conn",
    "    conn.connect()",
    "  File \"/usr/local/lib/python3.9/site-packages/urllib3/connection.py\", line 363, in connect",
    "    self.sock = conn = self._new_conn()",
    "  File \"/usr/local/lib/python3.9/site-packages/urllib3/connection.py\", line 186, in _new_conn",
    "    raise NewConnectionError(",
    "urllib3.exceptions.NewConnectionError: <urllib3.connection.HTTPSConnection object at 0x7f6469eae5b0>: Failed to establish a new connection: [Errno 101] Network is unreachable",
    "",
    "During handling of the above exception, another exception occurred:",
    "",
    "Traceback (most recent call last):",
    "  File \"/usr/local/lib/python3.9/site-packages/requests/adapters.py\", line 667, in send",
    "    resp = conn.urlopen(",
    "  File \"/usr/local/lib/python3.9/site-packages/urllib3/connectionpool.py\", line 801, in urlopen",
    "    retries = retries.increment(",
    "  File \"/usr/local/lib/python3.9/site-packages/urllib3/util/retry.py\", line 594, in increment",
    "    raise MaxRetryError(_pool, url, error or ResponseError(cause))",
    "urllib3.exceptions.MaxRetryError: HTTPSConnectionPool(host='100.66.31.9', port=443): Max retries exceeded with url: /api?type=keygen&user=t3-admin&password=Px3Kx%5B8SxN (Caused by NewConnectionError('<urllib3.connection.HTTPSConnection object at 0x7f6469eae5b0>: Failed to establish a new connection: [Errno 101] Network is unreachable'))",
    "",
    "During handling of the above exception, another exception occurred:",
    "",
    "Traceback (most recent call last):",
    "  File \"/tmp/palo_scripts/main.py\", line 67, in get_api_key",
    "    response = requests.get(url, params=params, verify=False)",
    "  File \"/usr/local/lib/python3.9/site-packages/requests/api.py\", line 73, in get",
    "    return request(\"get\", url, params=params, **kwargs)",
    "  File \"/usr/local/lib/python3.9/site-packages/requests/api.py\", line 59, in request",
    "    return session.request(method=method, url=url, **kwargs)",
    "  File \"/usr/local/lib/python3.9/site-packages/requests/sessions.py\", line 589, in request",
    "    resp = self.send(prep, **send_kwargs)",
    "  File \"/usr/local/lib/python3.9/site-packages/requests/sessions.py\", line 703, in send",
    "    r = adapter.send(request, **kwargs)",
    "  File \"/usr/local/lib/python3.9/site-packages/requests/adapters.py\", line 700, in send",
    "    raise ConnectionError(e, request=request)",
    "requests.exceptions.ConnectionError: HTTPSConnectionPool(host='100.66.31.9', port=443): Max retries exceeded with url: /api?type=keygen&user=t3-admin&password=Px3Kx%5B8SxN (Caused by NewConnectionError('<urllib3.connection.HTTPSConnection object at 0x7f6469eae5b0>: Failed to establish a new connection: [Errno 101] Network is unreachable'))",
    "",
    "During handling of the above exception, another exception occurred:",
    "",
    "Traceback (most recent call last):",
    "  File \"/tmp/palo_scripts/main.py\", line 176, in <module>",
    "    main()",
    "  File \"/tmp/palo_scripts/main.py\", line 104, in main",
    "    api_key = get_api_key(palo_ip, username, password)",
    "  File \"/tmp/palo_scripts/main.py\", line 82, in get_api_key",
    "    raise Exception(f\"An error occurred during the API Key retreival from device {palo_ip}: {e}\")",
    "Exception: An error occurred during the API Key retreival from device 100.66.31.9: HTTPSConnectionPool(host='100.66.31.9', port=443): Max retries exceeded with url: /api?type=keygen&user=t3-admin&password=Px3Kx%5B8SxN (Caused by NewConnectionError('<urllib3.connection.HTTPSConnection object at 0x7f6469eae5b0>: Failed to establish a new connection: [Errno 101] Network is unreachable'))"
  ],
  "_ansible_no_log": false,
  "_ansible_delegated_vars": {
    "ansible_host": "10.16.2.22",
    "ansible_port": null,
    "ansible_user": "tier3.global.ip"
  }
}


Here's how my main playbook looks:

---
- name: Lookup device in NetBox and update PrimaryIP
  hosts: localhost
  gather_facts: no
  connection: local
  vars:
    netbox_base: "https://netbox.gt-t.net/api/"
    scripts_dir: "scripts/"

  tasks:
  - name: Get vault passwords
    set_fact:
      vault: "{{ lookup('hashi_vault', 'secret=ansible/data/tss') }}"
    no_log: true

  - name: Set NetBox token as a fact
    set_fact:
      netbox_token: "{{ vault.netbox_soc_token }}"
    no_log: true

  # - name: Show incoming hostvars/extra_vars
  #   debug:
  #     var: hostvars[inventory_hostname]
  #   when: show_extra_vars | default(true)

  - name: Determine current GNID once
    set_fact:
      current_gnid: >-
        {{
            (hostvars[inventory_hostname].extra_vars.RequestDetails.GNID
               if (hostvars[inventory_hostname].extra_vars is defined
                   and hostvars[inventory_hostname].extra_vars.RequestDetails is defined)
               else RequestDetails.GNID)
        }}

  - name: Lookup PaloAlto firewall details in NetBox
    include_tasks: include_tasks/netbox_palo_fw_lookup.yml

  - name: Bail if no firewall entry was found
    fail:
      msg: "No device found with GNID {{ current_gnid }}"
    when: nb_primary_ip is not defined

  - name: Ensure extra_vars dict exists
    set_fact:
      extra_vars: {}
    when: extra_vars is not defined

  - name: Inject NetBox data into extra_vars.RequestDetails
    set_fact:
      extra_vars: >-
        {{ extra_vars
           | combine(
               {'RequestDetails':
                 (extra_vars.RequestDetails | default({}))
                 | combine({
                     'PrimaryIP'   : nb_primary_ip,
                     'role_id'     : nb_role_id,
                     'jumphost'    : nb_jumphost,
                     'panorama_ip' : nb_panorama_ip
                   })
               },
               recursive=true
             )
        }}

  - name: Show updated extra_vars
    debug:
      var: hostvars[inventory_hostname].extra_vars
    when:
      - show_extra_vars | default(true)
      - nb_primary_ip is defined

  - name: Serialise extra_vars for the Python script
    set_fact:
      extra_vars_json: "{{ extra_vars | to_json }}"
    no_log: true
  
  - name: Serialise extra_vars for the Python script
    set_fact:
      extra_vars_json: "{{ extra_vars | to_json }}"
    no_log: true

  # - name: Verify TCP 443 is open from {{ nb_jumphost }}
  #   wait_for:
  #     host: "{{ nb_primary_ip }}"
  #     port: 443
  #     timeout: 5
  #     state: started
  #   delegate_to: 10.160.2.22
  
  # - name: Palo-Alto API probe – keygen
  #   uri:
  #     url: "https://{{ nb_primary_ip }}/api/"
  #     validate_certs: no
  #     method: GET
  #     return_content: yes
  #     status_code: 200
  #     params:
  #       type: keygen
  #       user: "t3-admin"
  #       password: "Px3Kx[8SxN"
  #   delegate_to: 10.160.2.22
  #   register: api_ping
  #   failed_when: "'<response status=\"success\"' not in api_ping.content"

#===========================================

  # - name: Ensure script folder exists on {{ nb_jumphost }}
  #   file:
  #     path: /tmp/palo_scripts
  #     state: directory
  #     mode: '0755'
  #   delegate_to: "{{ nb_jumphost }}"
  #   when: nb_jumphost != 'localhost'

  # - name: Copy Python helper files to {{ nb_jumphost }}
  #   copy:
  #     src: "{{ item }}"
  #     dest: "/tmp/palo_scripts/{{ item | basename }}"
  #     mode: '0755'
  #   loop: "{{ lookup('fileglob', scripts_dir + '/*.py', wantlist=True) }}"
  #   delegate_to: "{{ nb_jumphost }}"
  #   when: nb_jumphost != 'localhost'

  # - name: Run main.py on {{ nb_jumphost }}
  #   command: >
  #     python3 {{
  #       (nb_jumphost == 'localhost')
  #       | ternary(scripts_dir + '/main.py', '/tmp/palo_scripts/main.py')
  #     }}
  #   delegate_to: "{{ nb_jumphost }}"
  #   environment:
  #     EXTRA_VARS: "{{ extra_vars_json }}"
  #   register: python_result

#===========================================

  # - name: FALSE Show effective UID and routing table (debug)
  #   command: |
  #     sh -c 'id -u && ip route get {{ nb_primary_ip }}'
  #   delegate_to: "{{ nb_jumphost }}"
  #   become: false

  # - name: TRUE Show effective UID and routing table (debug)
  #   command: |
  #     sh -c 'id -u && ip route get {{ nb_primary_ip }}'
  #   delegate_to: "{{ nb_jumphost }}"
  #   become: true

#+=====================================

  - name: Ensure script folder exists on {{ nb_jumphost }}
    file:
      path: /tmp/palo_scripts
      state: directory
      mode: '0755'
    become: false
    delegate_to: "{{ nb_jumphost }}"
    when: nb_jumphost != 'localhost'

  ###########################################################################
  # 7a. Copy helpers without sudo         (only when jumphost is remote)    #
  ###########################################################################
  - name: Copy Python helper files to {{ nb_jumphost }}
    copy:
      src: "{{ item }}"
      dest: "/tmp/palo_scripts/{{ item | basename }}"
      mode: '0755'
    loop: "{{ lookup('fileglob', scripts_dir + '/*.py', wantlist=True) }}"
    delegate_to: "{{ nb_jumphost }}"
    become: false                  # <─── force NO privilege escalation
    when: nb_jumphost != 'localhost'
  
  ###########################################################################
  # 7b. Run main.py exactly like your manual test                           #
  ###########################################################################
  - name: Run main.py on {{ nb_jumphost }}
    command: >
      python3 {{
        (nb_jumphost == 'localhost')
        | ternary(scripts_dir + '/main.py', '/tmp/palo_scripts/main.py')
      }}
    delegate_to: "{{ nb_jumphost }}"
    become: false                  # <─── force NO privilege escalation
    environment:
      EXTRA_VARS: "{{ extra_vars_json }}"
      HTTP_PROXY: ""
      HTTPS_PROXY: ""
      NO_PROXY: "{{ nb_primary_ip }}"
    register: python_result
#+========================================


  # - name: Run main.py
  #   ansible.builtin.script:
  #     cmd: main.py
  #     executable: /usr/bin/python3
  #   register: logNewNetboxDataVariable
  #   changed_when: false
  #   become: false
  #   delegate_to: 10.160.2.22

  - name: Show script stdout
    debug:
      var: python_result.stdout_lines
    when: show_extra_vars | default(true)
