{
  "changed": true,
  "stdout": "Gon Get API Key.",
  "stderr": "Traceback (most recent call last):\n  File \"/usr/local/lib/python3.9/site-packages/urllib3/connection.py\", line 174, in _new_conn\n    conn = connection.create_connection(\n  File \"/usr/local/lib/python3.9/site-packages/urllib3/util/connection.py\", line 95, in create_connection\n    raise err\n  File \"/usr/local/lib/python3.9/site-packages/urllib3/util/connection.py\", line 85, in create_connection\n    sock.connect(sa)\nOSError: [Errno 101] Network is unreachable\n\nDuring handling of the above exception, another exception occurred:\n\nTraceback (most recent call last):\n  File \"/usr/local/lib/python3.9/site-packages/urllib3/connectionpool.py\", line 715, in urlopen\n    httplib_response = self._make_request(\n  File \"/usr/local/lib/python3.9/site-packages/urllib3/connectionpool.py\", line 404, in _make_request\n    self._validate_conn(conn)\n  File \"/usr/local/lib/python3.9/site-packages/urllib3/connectionpool.py\", line 1060, in _validate_conn\n    conn.connect()\n  File \"/usr/local/lib/python3.9/site-packages/urllib3/connection.py\", line 363, in connect\n    self.sock = conn = self._new_conn()\n  File \"/usr/local/lib/python3.9/site-packages/urllib3/connection.py\", line 186, in _new_conn\n    raise NewConnectionError(\nurllib3.exceptions.NewConnectionError: <urllib3.connection.HTTPSConnection object at 0x7f7e4b0dba60>: Failed to establish a new connection: [Errno 101] Network is unreachable\n\nDuring handling of the above exception, another exception occurred:\n\nTraceback (most recent call last):\n  File \"/usr/local/lib/python3.9/site-packages/requests/adapters.py\", line 667, in send\n    resp = conn.urlopen(\n  File \"/usr/local/lib/python3.9/site-packages/urllib3/connectionpool.py\", line 801, in urlopen\n    retries = retries.increment(\n  File \"/usr/local/lib/python3.9/site-packages/urllib3/util/retry.py\", line 594, in increment\n    raise MaxRetryError(_pool, url, error or ResponseError(cause))\nurllib3.exceptions.MaxRetryError: HTTPSConnectionPool(host='100.66.31.9', port=443): Max retries exceeded with url: /api/?type=keygen&user=t3-admin&password=Px3Kx%5B8SxN (Caused by NewConnectionError('<urllib3.connection.HTTPSConnection object at 0x7f7e4b0dba60>: Failed to establish a new connection: [Errno 101] Network is unreachable'))\n\nDuring handling of the above exception, another exception occurred:\n\nTraceback (most recent call last):\n  File \"/tmp/palo_api_probe.py\", line 26, in <module>\n    main()\n  File \"/tmp/palo_api_probe.py\", line 15, in main\n    r = requests.get(url, verify=False, timeout=10,\n  File \"/usr/local/lib/python3.9/site-packages/requests/api.py\", line 73, in get\n    return request(\"get\", url, params=params, **kwargs)\n  File \"/usr/local/lib/python3.9/site-packages/requests/api.py\", line 59, in request\n    return session.request(method=method, url=url, **kwargs)\n  File \"/usr/local/lib/python3.9/site-packages/requests/sessions.py\", line 589, in request\n    resp = self.send(prep, **send_kwargs)\n  File \"/usr/local/lib/python3.9/site-packages/requests/sessions.py\", line 703, in send\n    r = adapter.send(request, **kwargs)\n  File \"/usr/local/lib/python3.9/site-packages/requests/adapters.py\", line 700, in send\n    raise ConnectionError(e, request=request)\nrequests.exceptions.ConnectionError: HTTPSConnectionPool(host='100.66.31.9', port=443): Max retries exceeded with url: /api/?type=keygen&user=t3-admin&password=Px3Kx%5B8SxN (Caused by NewConnectionError('<urllib3.connection.HTTPSConnection object at 0x7f7e4b0dba60>: Failed to establish a new connection: [Errno 101] Network is unreachable'))",
  "rc": 1,
  "cmd": [
    "python3",
    "/tmp/palo_api_probe.py"
  ],
  "start": "2025-04-29 21:11:45.764886",
  "end": "2025-04-29 21:11:45.870869",
  "delta": "0:00:00.105983",
  "msg": "non-zero return code",
  "invocation": {
    "module_args": {
      "_raw_params": "python3 /tmp/palo_api_probe.py",
      "_uses_shell": false,
      "stdin_add_newline": true,
      "strip_empty_ends": true,
      "argv": null,
      "chdir": null,
      "executable": null,
      "creates": null,
      "removes": null,
      "stdin": null
    }
  },
  "stdout_lines": [
    "Gon Get API Key."
  ],
  "stderr_lines": [
    "Traceback (most recent call last):",
    "  File \"/usr/local/lib/python3.9/site-packages/urllib3/connection.py\", line 174, in _new_conn",
    "    conn = connection.create_connection(",
    "  File \"/usr/local/lib/python3.9/site-packages/urllib3/util/connection.py\", line 95, in create_connection",
    "    raise err",
    "  File \"/usr/local/lib/python3.9/site-packages/urllib3/util/connection.py\", line 85, in create_connection",
    "    sock.connect(sa)",
    "OSError: [Errno 101] Network is unreachable",
    "",
    "During handling of the above exception, another exception occurred:",
    "",
    "Traceback (most recent call last):",
    "  File \"/usr/local/lib/python3.9/site-packages/urllib3/connectionpool.py\", line 715, in urlopen",
    "    httplib_response = self._make_request(",
    "  File \"/usr/local/lib/python3.9/site-packages/urllib3/connectionpool.py\", line 404, in _make_request",
    "    self._validate_conn(conn)",
    "  File \"/usr/local/lib/python3.9/site-packages/urllib3/connectionpool.py\", line 1060, in _validate_conn",
    "    conn.connect()",
    "  File \"/usr/local/lib/python3.9/site-packages/urllib3/connection.py\", line 363, in connect",
    "    self.sock = conn = self._new_conn()",
    "  File \"/usr/local/lib/python3.9/site-packages/urllib3/connection.py\", line 186, in _new_conn",
    "    raise NewConnectionError(",
    "urllib3.exceptions.NewConnectionError: <urllib3.connection.HTTPSConnection object at 0x7f7e4b0dba60>: Failed to establish a new connection: [Errno 101] Network is unreachable",
    "",
    "During handling of the above exception, another exception occurred:",
    "",
    "Traceback (most recent call last):",
    "  File \"/usr/local/lib/python3.9/site-packages/requests/adapters.py\", line 667, in send",
    "    resp = conn.urlopen(",
    "  File \"/usr/local/lib/python3.9/site-packages/urllib3/connectionpool.py\", line 801, in urlopen",
    "    retries = retries.increment(",
    "  File \"/usr/local/lib/python3.9/site-packages/urllib3/util/retry.py\", line 594, in increment",
    "    raise MaxRetryError(_pool, url, error or ResponseError(cause))",
    "urllib3.exceptions.MaxRetryError: HTTPSConnectionPool(host='100.66.31.9', port=443): Max retries exceeded with url: /api/?type=keygen&user=t3-admin&password=Px3Kx%5B8SxN (Caused by NewConnectionError('<urllib3.connection.HTTPSConnection object at 0x7f7e4b0dba60>: Failed to establish a new connection: [Errno 101] Network is unreachable'))",
    "",
    "During handling of the above exception, another exception occurred:",
    "",
    "Traceback (most recent call last):",
    "  File \"/tmp/palo_api_probe.py\", line 26, in <module>",
    "    main()",
    "  File \"/tmp/palo_api_probe.py\", line 15, in main",
    "    r = requests.get(url, verify=False, timeout=10,",
    "  File \"/usr/local/lib/python3.9/site-packages/requests/api.py\", line 73, in get",
    "    return request(\"get\", url, params=params, **kwargs)",
    "  File \"/usr/local/lib/python3.9/site-packages/requests/api.py\", line 59, in request",
    "    return session.request(method=method, url=url, **kwargs)",
    "  File \"/usr/local/lib/python3.9/site-packages/requests/sessions.py\", line 589, in request",
    "    resp = self.send(prep, **send_kwargs)",
    "  File \"/usr/local/lib/python3.9/site-packages/requests/sessions.py\", line 703, in send",
    "    r = adapter.send(request, **kwargs)",
    "  File \"/usr/local/lib/python3.9/site-packages/requests/adapters.py\", line 700, in send",
    "    raise ConnectionError(e, request=request)",
    "requests.exceptions.ConnectionError: HTTPSConnectionPool(host='100.66.31.9', port=443): Max retries exceeded with url: /api/?type=keygen&user=t3-admin&password=Px3Kx%5B8SxN (Caused by NewConnectionError('<urllib3.connection.HTTPSConnection object at 0x7f7e4b0dba60>: Failed to establish a new connection: [Errno 101] Network is unreachable'))"
  ],
  "_ansible_no_log": false,
  "_ansible_delegated_vars": {
    "ansible_host": "10.16.2.22",
    "ansible_port": null,
    "ansible_user": "tier3.global.ip"
  }
}
